Workbook

Sheet Sheet2
B1: 列0 | C1: 列1 | D1: 列2 | E1: 列3 | F1: 列4 | G1: 列5 | H1: 列6 | I1: 列7 | J1: 列8 | K1: 列9 | L1: 列10 | M1: 列11 | N1: 列12 | O1: 列13 | P1: 列14 | Q1: 列15 | R1: 列16 | S1: 列17 | T1: 列18 | U1: 列19 | V1: 列20 | W1: 列21 | X1: 列22 | Y1: 列23 | Z1: 列24 | AA1: 列25 | AB1: 列26 | AC1: 列27 | AD1: 列28 | AE1: 列29 | AF1: 列30 | AG1: 列31 | AH1: 列32 | AI1: 列33 | AJ1: 列34 | AK1: 列35 | AL1: 列36 | AM1: 列37 | AN1: 列38 | AO1: 列39 | AP1: 列40 | AQ1: 列41 | AR1: 列42 | AS1: 列43 | AT1: 列44 | AU1: 列45
B2: 说明 | C2: 全回热，最大制冷量 | D2: 无回热，最大排温，最大制冷量 | E2: 全回热 | F2: 全回热 | G2: 全回热 | H2: 不回热 | I2: 不回热 | J2: 不回热 | K2: 不回热 | L2: 不回热 | M2: 不回热 | N2: 全回热 | O2: 全回热 | P2: 全回热 | Q2: 全回热 | R2: 不回热 | S2: 不回热 | T2: 不回热 | U2: 不回热 | V2: 不回热 | W2: 全回热 | X2: 全回热 | Y2: 全回热 | Z2: 全回热 | AA2: 无效，图110123 | AB2: 不回热 | AC2: 不回热 | AD2: 不回热 | AE2: 不回热 | AF2: 回热 | AG2: 回热 | AH2: 回热 | AI2: 回热 | AJ2: 回热 | AK2: 回热 | AL2: 回热 | AM2: 回热 | AN2: 回热 | AO2: 回热 | AP2: 回热 | AQ2: 回热 | AR2: 回热 | AS2: 回热 | AT2: 回热 | AU2: 回热
A3: 类别 | B3: 项目 | C3: 组1 | D3: 组2 | E3: 组3 | F3: 组4 | G3: 组5 | H3: 组6 | I3: 组7 | J3: 组8 | K3: 组9 | L3: 组10 | M3: 组11 | N3: 组12 | O3: 组13 | P3: 组14 | Q3: 组15 | R3: 组16 | S3: 组17 | T3: 组18 | U3: 组19 | V3: 组20 | W3: 组21 | X3: 组22 | Y3: 组23 | Z3: 组24 | AA3: 组25 | AB3: 组26 | AC3: 组27 | AD3: 组28 | AE3: 组29 | AF3: 组30 | AG3: 组31 | AH3: 组32 | AI3: 组33 | AJ3: 组34 | AK3: 组35 | AL3: 组36 | AM3: 组37 | AN3: 组38 | AO3: 组39 | AP3: 组40 | AQ3: 组41 | AR3: 组42 | AS3: 组43 | AT3: 组44 | AU3: 组45
A4: 环境参数 | B4: 室内干球 | C4: 26.9 | D4: 27.1 | E4: 27 | F4: 27 | G4: 27 | H4: 26.9 | I4: 26.9 | J4: 27 | K4: 27 | L4: 27 | M4: 26.9 | N4: 27 | O4: 27 | P4: 27 | Q4: 27 | R4: 27 | S4: 27 | T4: 27 | U4: 27 | V4: 26.9 | W4: 27 | X4: 27 | Y4: 27 | Z4: 27 | AB4: 27 | AC4: 27 | AD4: 27 | AE4: 26.9 | AF4: 27 | AG4: 27 | AH4: 27 | AI4: 27 | AJ4: 27 | AK4: 27.1 | AL4: 27 | AM4: 27 | AN4: 26.9 | AO4: 27 | AP4: 27 | AQ4: 27 | AR4: 27
B5: 室内湿球 | C5: 19.5 | D5: 19.5 | E5: 19.5 | F5: 19.5 | G5: 19.5 | H5: 19.5 | I5: 19.5 | J5: 19.5 | K5: 19.4 | L5: 19.5 | M5: 19.5 | N5: 19.5 | O5: 19.5 | P5: 19.5 | Q5: 19.5 | R5: 19.5 | S5: 19.5 | T5: 19.5 | U5: 19.5 | V5: 19.5 | W5: 19.5 | X5: 19.5 | Y5: 19.5 | Z5: 19.5 | AB5: 19.5 | AC5: 19.5 | AD5: 19.5 | AE5: 19.5 | AF5: 19.5 | AG5: 19.4 | AH5: 19.4 | AI5: 19.5 | AJ5: 19.5 | AK5: 19.5 | AL5: 19.5 | AM5: 19.5 | AN5: 19.5 | AO5: 19.5 | AP5: 19.5 | AQ5: 19.6 | AR5: 19.5
B6: 室外干球 | C6: 29.9 | D6: 30.1 | E6: 30 | F6: 30.1 | G6: 30.3 | H6: 30.1 | I6: 29.9 | J6: 29.7 | K6: 29.9 | L6: 29.9 | M6: 30 | N6: 30.1 | O6: 29.9 | P6: 30.1 | Q6: 30.1 | R6: 29.9 | S6: 29.9 | T6: 30 | U6: 29.8 | V6: 30.1 | W6: 30 | X6: 30 | Y6: 30 | Z6: 30 | AB6: 30.2 | AC6: 29.9 | AD6: 30 | AE6: 31.1 | AF6: 29.9 | AG6: 30.2 | AH6: 30 | AI6: 30 | AJ6: 30.3 | AK6: 29.8 | AL6: 29.8 | AM6: 29.8 | AN6: 30 | AO6: 30.2 | AP6: 30.2 | AQ6: 29.9 | AR6: 29.8
B7: 室外湿球 | C7: 21.9 | D7: 21.8 | E7: 21.7 | F7: 22.1 | G7: 22.4 | H7: 21.9 | I7: 21.8 | J7: 21.6 | K7: 21.7 | L7: 21.7 | M7: 21.9 | N7: 21.9 | O7: 21.8 | P7: 22.1 | Q7: 21.9 | R7: 21.9 | S7: 21.8 | T7: 21.7 | U7: 21.8 | V7: 21.8 | W7: 21.9 | X7: 21.7 | Y7: 21.9 | Z7: 21.8 | AB7: 21.8 | AC7: 21.9 | AD7: 22.2 | AE7: 22.8 | AF7: 21.7 | AG7: 22.3 | AH7: 21.9 | AI7: 21.9 | AJ7: 22.4 | AK7: 21.7 | AL7: 21.7 | AM7: 21.5 | AN7: 22.6 | AO7: 22.2 | AP7: 22.2 | AQ7: 21.8 | AR7: 21.8
A8: 温度/℃ | B8: 吸气温度 | C8: 33 | D8: 17 | E8: 29.56 | F8: 29.68 | G8: 29.96 | H8: 9.75 | I8: 11.77 | J8: 8.04 | K8: 5.53 | L8: 3.93 | M8: 2.05 | N8: 27.14 | O8: 28.06 | P8: 26 | Q8: 26.6 | R8: -2.86 | S8: -3.16 | T8: -3.2 | U8: -3.14 | V8: -2.92 | W8: 28.39 | X8: 27.27 | Y8: 26.34 | Z8: 25.73 | AB8: -3.51 | AC8: -3.56 | AD8: -3.36 | AE8: -2.89 | AF8: 27.62 | AG8: 26.93 | AH8: 26.27 | AI8: 25.51 | AJ8: -2.5 | AK8: 25.92 | AL8: 25.16 | AM8: 26.6 | AN8: 15.63 | AO8: 17.96 | AP8: 18.84 | AQ8: -0.65 | AR8: 0.65
B9: 排气温度 | C9: 134.13 | D9: 134.11 | E9: 121.68 | F9: 135.45 | G9: 130.44 | H9: 123.3 | I9: 130.85 | J9: 116.64 | K9: 107.21 | L9: 101.2 | M9: 93.06 | N9: 121.6 | O9: 116.98 | P9: 124.46 | Q9: 123.23 | R9: 100.24 | S9: 94.03 | T9: 89.63 | U9: 87.04 | V9: 84.84 | W9: 116.43 | X9: 121.58 | Y9: 124.5 | Z9: 126.31 | AB9: 90.89 | AC9: 88.72 | AD9: 87.11 | AE9: 85.67 | AF9: 115.23 | AG9: 120.69 | AH9: 123.43 | AI9: 125.76 | AJ9: 111.99 | AK9: 122.45 | AL9: 124.45 | AM9: 118.05 | AN9: 101.38 | AO9: 108.4 | AP9: 114.62 | AQ9: 86.36 | AR9: 95.09
B10: 室外换热进口 | C10: 127.88 | D10: 128.23 | E10: 117.83 | F10: 129.8 | G10: 125.14 | H10: 118.54 | I10: 125.82 | J10: 112.26 | K10: 103.56 | L10: 97.68 | M10: 90.47 | N10: 116.97 | O10: 112.58 | P10: 119.88 | Q10: 118.78 | R10: 97.47 | S10: 91.23 | T10: 87.31 | U10: 84.43 | V10: 82.29 | W10: 111.95 | X10: 117.24 | Y10: 119.58 | Z10: 121.28 | AB10: 88.07 | AC10: 86.1 | AD10: 84.48 | AE10: 83.17 | AF10: 110.91 | AG10: 116.08 | AH10: 118.63 | AI10: 121.31 | AJ10: 109.13 | AK10: 119.73 | AL10: 119.74 | AM10: 113.64 | AN10: 98.43 | AO10: 105.12 | AP10: 110.61 | AQ10: 84.26 | AR10: 92.58
B11: 室外换热出口 | C11: 34.51 | D11: 34.23 | E11: 35.79 | F11: 20.05 | G11: 28.12 | H11: 32.63 | I11: 23.18 | J11: 12.08 | K11: 30.87 | L11: 28.88 | M11: 36.54 | N11: 36.73 | O11: 36.89 | P11: 35.4 | Q11: 35.03 | R11: 32.43 | S11: 33.73 | T11: 34.12 | U11: 36.34 | V11: 37.15 | W11: 36.65 | X11: 31.67 | Y11: 33.79 | Z11: 36.26 | AB11: 34.23 | AC11: 34.17 | AD11: 35.24 | AE11: 35.55 | AF11: 37.02 | AG11: 36.61 | AH11: 35.69 | AI11: 36.06 | AJ11: 30.15 | AK11: 34.98 | AL11: 29.48 | AM11: 33.92 | AN11: 36.7 | AO11: 35.94 | AP11: 35.65 | AQ11: 36.59 | AR11: 34.36
B12: 回热器高压进口 | C12: 34.38 | D12: 34.15 | E12: 35.49 | F12: 34.04 | G12: 35.03 | H12: 33.23 | I12: 32.62 | J12: 33.27 | K12: 34.12 | L12: 34.56 | M12: 35.25 | N12: 35.05 | O12: 35.02 | P12: 34.43 | Q12: 34.77 | R12: 32.83 | S12: 33.41 | T12: 33.9 | U12: 34.31 | V12: 34.88 | W12: 34.95 | X12: 34.92 | Y12: 34.48 | Z12: 34.13 | AB12: 34.16 | AC12: 34.13 | AD12: 34.65 | AE12: 35.26 | AF12: 34.92 | AG12: 34.85 | AH12: 34.59 | AI12: 34.12 | AJ12: 32.88 | AK12: 34.85 | AL12: 34.3 | AM12: 35.14 | AN12: 35.58 | AO12: 35.31 | AP12: 34.79 | AQ12: 34.79 | AR12: 33.84
B13: 回热器高压出口 | C13: 32.83 | D13: 33.98 | E13: 28.7 | F13: 26.81 | G13: 27.5 | H13: 32.98 | I13: 32.44 | J13: 33.05 | K13: 33.82 | L13: 34.23 | M13: 34.84 | N13: 24.4 | O13: 27.08 | P13: 22.26 | Q13: 23.24 | R13: 32.54 | S13: 33.13 | T13: 33.62 | U13: 33.97 | V13: 34.48 | W13: 27.74 | X13: 24.2 | Y13: 22.3 | Z13: 21.29 | AB13: 33.83 | AC13: 33.81 | AD13: 35.29 | AE13: 34.91 | AF13: 26.43 | AG13: 23.77 | AH13: 22.28 | AI13: 21 | AJ13: 32.6 | AK13: 22.56 | AL13: 221.07 | AM13: 24.59 | AN13: 19.92 | AO13: 18.5 | AP13: 16.89 | AQ13: 12.32 | AR13: 10.66
B14: 阀前温度 | C14: 32.21 | D14: 33.38 | E14: 28.18 | F14: 26.05 | G14: 27.15 | H14: 32.21 | I14: 31.61 | J14: 32.42 | K14: 33.16 | L14: 33.65 | M14: 34.67 | N14: 24.43 | O14: 26.92 | P14: 22.18 | Q14: 23.21 | R14: 32.26 | S14: 32.68 | T14: 33.11 | U14: 33.72 | V14: 34.02 | W14: 27.5 | X14: 24.01 | Y14: 22.05 | Z14: 21.29 | AB14: 33.25 | AC14: 33.17 | AD14: 33.79 | AE14: 34.11 | AF14: 26.49 | AG14: 23.36 | AH14: 22.41 | AI14: 20.9 | AJ14: 32.08 | AK14: 22.2 | AL14: 20.97 | AM14: 24.53 | AN14: 19.78 | AO14: 18.42 | AP14: 16.72 | AQ14: 12.53 | AR14: 10.94
B15: 阀后温度 | C15: 2.2 | D15: -1.49 | E15: 4.39 | F15: 2.36 | G15: 3.06 | H15: 2.67 | I15: 2.02 | J15: 3.16 | K15: 4.09 | L15: 4.73 | M15: 5.87 | N15: 3.64 | O15: 4.68 | P15: 3.08 | Q15: 3.32 | R15: 4.76 | S15: 5.08 | T15: 5.49 | U15: 5.76 | V15: 6.28 | W15: 4.7 | X15: 3.27 | Y15: 2.72 | Z15: 2.42 | AB15: 5.06 | AC15: 5.23 | AD15: 5.6 | AE15: 6.06 | AF15: 4.9 | AG15: 3.7 | AH15: 3.22 | AI15: 2.28 | AJ15: 5.12 | AK15: 3.35 | AL15: 2.89 | AM15: 4.25 | AN15: 5.05 | AO15: 3.98 | AP15: 3.15 | AQ15: 4.37 | AR15: 3.24
B16: 主换热器进口 | C16: 2.16 | D16: -1.42 | E16: 4.26 | F16: 2.31 | G16: 3.05 | H16: 2.66 | I16: 2.04 | J16: 3.06 | K16: 4.01 | L16: 4.64 | M16: 5.74 | N16: 3.76 | O16: 4.67 | P16: 3.2 | Q16: 3.41 | R16: 4.71 | S16: 4.99 | T16: 5.32 | U16: 5.62 | V16: 6.11 | W16: 4.68 | X16: 3.32 | Y16: 2.78 | Z16: 2.55 | AB16: 4.93 | AC16: 5.09 | AD16: 5.44 | AE16: 5.92 | AF16: 4.87 | AG16: 3.78 | AH16: 3.37 | AI16: 3.02 | AJ16: 4.89 | AK16: 3.22 | AL16: 2.79 | AM16: 4.14 | AN16: 5.02 | AO16: 4.01 | AP16: 3.23 | AQ16: 4.51 | AR16: 3.37
B17: 主换热器出口 | C17: 18.19 | D17: 18.91 | E17: 3.92 | F17: 9.49 | G17: 6.86 | H17: 11.61 | I17: 13.37 | J17: 10.19 | K17: 8.2 | L17: 6.86 | M17: 5.52 | N17: 0.8 | O17: 1.55 | P17: 0.39 | Q17: 0.55 | R17: 0.49 | S17: 0.53 | T17: 0.68 | U17: 0.9 | V17: 1.21 | W17: 1.71 | X17: 0.57 | Y17: 0.16 | Z17: -0.04 | AB17: 0.47 | AC17: 0.55 | AD17: 0.82 | AE17: 1.47 | AF17: 2.08 | AG17: 1.15 | AH17: 0.83 | AI17: 0.59 | AJ17: 1.33 | AK17: 0.83 | AL17: 0.48 | AM17: 1.63 | AN17: 2.81 | AO17: 1.85 | AP17: 1.2 | AQ17: 2.54 | AR17: 1.62
B18: 储液器进口 | C18: 17.04 | D18: 17.75 | E18: 3.01 | F18: 8.55 | G18: 5.88 | H18: 10.39 | I18: 12.19 | J18: 8.94 | K18: 6.81 | L18: 5.4 | M18: 4.03 | N18: -0.11 | O18: 0.61 | P18: -0.54 | Q18: -0.38 | R18: -0.75 | S18: -0.75 | T18: -0.64 | U18: -0.46 | V18: -0.2 | W18: 0.8 | X18: -0.32 | Y18: -0.71 | Z18: -0.92 | AB18: -0.86 | AC18: -0.82 | AD18: -0.54 | AE18: 0 | AF18: 1.2 | AG18: 0.27 | AH18: -0.06 | AI18: -0.31 | AJ18: 0.49 | AK18: 0.27 | AL18: -0.1 | AM18: 0.98 | AN18: 2.02 | AO18: 1.09 | AP18: 0.45 | AQ18: 1.65 | AR18: 0.76
B19: 储液器出口 | C19: 17.21 | D19: 18.08 | E19: 3.08 | F19: 8.89 | G19: 6.17 | H19: 10.67 | I19: 12.57 | J19: 9.28 | K19: 7.06 | L19: 5.69 | M19: 4.17 | N19: -0.48 | O19: 0.3 | P19: -0.94 | Q19: -0.79 | R19: -0.95 | S19: -1.12 | T19: -1.07 | U19: -0.9 | V19: -0.6 | W19: 0.52 | X19: -0.62 | Y19: -1.04 | Z19: -1.22 | AB19: -1.29 | AC19: -1.24 | AD19: -0.96 | AE19: -0.41 | AF19: 0.87 | AG19: -0.1 | AH19: -0.4 | AI19: -0.7 | AJ19: 0 | AK19: -0.2 | AL19: -0.54 | AM19: 0.61 | AN19: 1.59 | AO19: 0.74 | AP19: 0.12 | AQ19: 1.24 | AR19: 0.42
B20: 回热器低压进口 | C20: 15.87 | D20: 30.35 | E20: 1.69 | F20: 7.88 | G20: 5.13 | H20: 27.03 | I20: 28.81 | J20: 30.68 | K20: 32.08 | L20: 32.68 | M20: 31.37 | N20: -2.38 | O20: -1.6 | P20: -2.74 | Q20: -2.61 | R20: 28.4 | S20: 30.48 | T20: 31.56 | U20: 32.47 | V20: 32.85 | W20: -1.29 | X20: -2.44 | Y20: -2.79 | Z20: -2.99 | AB20: 28.29 | AC20: 31.05 | AD20: 32.13 | AE20: 32.44 | AF20: -1.03 | AG20: -1.88 | AH20: -2.18 | AI20: -2.44 | AJ20: 25.76 | AK20: -1.88 | AL20: -2.2 | AM20: -1.09 | AN20: -0.34 | AO20: -1.14 | AP20: -1.67 | AQ20: -0.86 | AR20: -1.59
B21: 回热器低压出口 | C21: 32.21 | D21: 33.38 | E21: 30.54 | F21: 26.98 | G21: 30.37 | H21: 31.15 | I21: 30.66 | J21: 30.7 | K21: 33.16 | L21: 33.65 | M21: 34.67 | N21: 28.05 | O21: 28.76 | P21: 27 | Q21: 27.56 | R21: 32.26 | S21: 30.06 | T21: 30.33 | U21: 30.49 | V21: 30.86 | W21: 28.92 | X21: 27.93 | Y21: 27.2 | Z21: 26.29 | AB21: 30.59 | AC21: 30.57 | AD21: 30.75 | AE21: 30.63 | AF21: 28.32 | AG21: 27.77 | AH21: 27.15 | AI21: 26.49 | AJ21: 30.55 | AK21: 27.7 | AL21: 27.08 | AM21: 28.22 | AN21: 18.74 | AO21: 20.47 | AP21: 21.31 | AQ21: 2.57 | AR21: 4.33
A22: 压力/Mpa | B22: 吸气压力 | C22: 2.8 | D22: 2.5 | E22: 3.14 | F22: 2.97 | G22: 3.05 | H22: 2.92 | I22: 2.9 | J22: 2.94 | K22: 2.99 | L22: 3.02 | M22: 3.08 | N22: 3.18 | O22: 3.24 | P22: 3.15 | Q22: 3.16 | R22: 3.15 | S22: 3.13 | T22: 3.13 | U22: 3.14 | V22: 3.16 | W22: 3.26 | X22: 3.17 | Y22: 3.14 | Z22: 3.12 | AB22: 3.12 | AC22: 3.12 | AD22: 3.14 | AE22: 3.2 | AF22: 3.3 | AG22: 3.22 | AH22: 3.2 | AI22: 3.18 | AJ22: 3.25 | AK22: 3.21 | AL22: 3.18 | AM22: 3.27 | AN22: 3.37 | AO22: 3.29 | AP22: 3.25 | AQ22: 3.31 | AR22: 3.26
B23: 排气压力 | C23: 8.18 | D23: 8.51 | E23: 8.6 | F23: 9.04 | G23: 8.88 | H23: 9.8 | I23: 10.01 | J23: 9.59 | K23: 9.36 | L23: 9.2 | M23: 9.01 | N23: 8.81 | O23: 8.54 | P23: 9.04 | Q23: 8.94 | R23: 10.57 | S23: 10.04 | T23: 9.7 | U23: 9.49 | V23: 9.36 | W23: 8.46 | X23: 8.74 | Y23: 8.93 | Z23: 9.07 | AA23: 9.1 | AB23: 9.68 | AC23: 9.51 | AD23: 9.42 | AE23: 9.61 | AF23: 8.51 | AG23: 8.76 | AH23: 8.95 | AI23: 9.14 | AJ23: 11.48 | AK23: 8.83 | AL23: 8.95 | AM23: 8.6 | AN23: 8.68 | AO23: 8.82 | AP23: 9.02 | AQ23: 9.21 | AR23: 9.58
B24: 气冷进口 | C24: 8.053 | D24: 8.512 | E24: 8.534 | F24: 8.899 | G24: 8.835 | H24: 9.863 | I24: 10.043 | J24: 9.587 | K24: 9.396 | L24: 9.189 | M24: 8.993 | N24: 8.824 | O24: 8.534 | P24: 9.012 | Q24: 8.929 | R24: 10.559 | S24: 10.059 | T24: 9.678 | U24: 9.451 | V24: 9.349 | W24: 8.454 | X24: 8.719 | Y24: 8.918 | Z24: 9.076 | AB24: 9.684 | AC24: 9.512 | AD24: 9.09 | AE24: 9.601 | AF24: 8.456 | AG24: 8.76 | AH24: 8.91 | AI24: 9.142 | AJ24: 11.495 | AK24: 8.83 | AL24: 8.946 | AM24: 8.586 | AN24: 8.666 | AO24: 8.791 | AP24: 8.968 | AQ24: 9.222 | AR24: 9.568
B25: 气冷出口 | C25: 8.172 | D25: 8.367 | E25: 8.407 | F25: 8.89 | G25: 8.727 | H25: 9.708 | I25: 9.921 | J25: 9.471 | K25: 9.227 | L25: 9.031 | M25: 8.807 | N25: 8.642 | O25: 8.36 | P25: 8.896 | Q25: 8.763 | R25: 10.413 | S25: 9.88 | T25: 9.526 | U25: 9.308 | V25: 9.156 | W25: 8.277 | X25: 8.578 | Y25: 8.785 | Z25: 8.929 | AB25: 9.512 | AC25: 9.333 | AE25: 9.427 | AF25: 8.324 | AG25: 8.597 | AH25: 8.805 | AI25: 9.001 | AJ25: 11.399 | AK25: 8.678 | AL25: 8.824 | AM25: 8.445 | AN25: 8.426 | AO25: 8.631 | AP25: 8.871 | AQ25: 9.031 | AR25: 9.407
B26: 阀前压力 | C26: 7.953 | D26: 8.359 | E26: 8.294 | F26: 8.815 | G26: 8.648 | H26: 9.598 | I26: 9.835 | J26: 9.368 | K26: 9.098 | L26: 8.901 | M26: 8.661 | N26: 8.54 | O26: 8.221 | P26: 8.804 | Q26: 8.672 | R26: 10.318 | S26: 9.749 | T26: 9.379 | U26: 9.147 | V26: 8.988 | W26: 8.137 | X26: 8.469 | Y26: 8.702 | Z26: 8.839 | AB26: 9.377 | AC26: 9.188 | AD26: 9.241 | AE26: 9.296 | AF26: 8.086 | AG26: 8.475 | AH26: 8.693 | AI26: 8.923 | AJ26: 11.276 | AK26: 8.58 | AL26: 8.71 | AM26: 8.27 | AN26: 8.329 | AO26: 8.515 | AP26: 8.864 | AQ26: 8.847 | AR26: 9.29
B27: 主换热器进口 | C27: 3.619 | D27: 3.301 | E27: 3.855 | F27: 3.665 | G27: 3.741 | H27: 3.692 | I27: 3.632 | J27: 3.749 | K27: 3.831 | L27: 3.883 | M27: 4.007 | N27: 3.82 | O27: 3.923 | P27: 3.765 | Q27: 3.787 | R27: 3.917 | S27: 3.931 | T27: 3.966 | U27: 4.004 | V27: 4.059 | W27: 3.92 | X27: 3.798 | Y27: 3.738 | Z27: 3.711 | AB27: 3.939 | AC27: 3.958 | AE27: 4.042 | AF27: 3.955 | AG27: 3.852 | AH27: 3.798 | AI27: 3.771 | AJ27: 3.934 | AK27: 3.803 | AL27: 3.765 | AM27: 3.877 | AN27: 3.98 | AO27: 3.879 | AP27: 3.793 | AQ27: 3.953 | AR27: 3.847
B28: 主换热器出口 | C28: 3.149 | D28: 2.794 | E28: 3.489 | F28: 3.301 | G28: 3.386 | H28: 3.253 | I28: 3.201 | J28: 3.277 | K28: 3.345 | L28: 3.391 | M28: 3.472 | N28: 3.505 | O28: 3.586 | P28: 3.475 | Q28: 3.489 | R28: 3.481 | S28: 3.486 | T28: 3.494 | U28: 3.524 | V28: 3.546 | W28: 3.608 | X28: 3.494 | Y28: 3.456 | Z28: 3.434 | AB28: 3.486 | AC28: 3.491 | AD28: 3.521 | AE28: 3.473 | AF28: 3.654 | AG28: 3.551 | AH28: 3.516 | AI28: 3.489 | AJ28: 3.559 | AK28: 3.527 | AL28: 3.494 | AM28: 3.603 | AN28: 3.711 | AO28: 3.613 | AP28: 3.567 | AQ28: 3.687 | AR28: 3.605
B29: 储液器进口
A30: 性能 | B30: 电压/V | C30: 345 | D30: 345 | E30: 345 | F30: 345 | G30: 345 | H30: 345 | I30: 345 | J30: 345 | K30: 345 | L30: 345 | M30: 345 | N30: 345 | O30: 345 | P30: 345 | Q30: 345 | R30: 345 | S30: 345 | T30: 345 | U30: 345 | V30: 345 | W30: 345 | X30: 345 | Y30: 345 | Z30: 345 | AA30: 345 | AB30: 345 | AC30: 345 | AD30: 345 | AE30: 345 | AF30: 345 | AG30: 345 | AH30: 345 | AI30: 345 | AJ30: 345 | AK30: 345 | AL30: 345 | AM30: 345 | AN30: 345 | AO30: 345 | AP30: 345 | AQ30: 345 | AR30: 345
B31: 电流/A | C31: 6.8 | D31: 7 | E31: 7.2 | F31: 7.5 | G31: 7.4 | H31: 8.2 | I31: 8.3 | J31: 8 | K31: 7.8 | L31: 7.7 | M31: 7.6 | N31: 7.3 | O31: 7.1 | P31: 7.5 | Q31: 7.4 | R31: 8.9 | S31: 8.4 | T31: 8.1 | U31: 8 | V31: 7.9 | W31: 7 | X31: 7.3 | Y31: 7.4 | Z31: 7.5 | AB31: 8.1 | AC31: 7.95 | AD31: 7.9 | AE31: 8 | AF31: 7 | AG31: 7.3 | AH31: 7.4 | AI31: 7.6 | AJ31: 9.6 | AK31: 7.3 | AL31: 7.4 | AM31: 7.1 | AN31: 7.2 | AO31: 7.3 | AP31: 7.5 | AQ31: 7.7 | AR31: 8
B32: 充注量/g | C32: 400 | D32: 400 | E32: 500 | F32: 500 | G32: 500 | H32: 500 | I32: 500 | J32: 500 | K32: 500 | L32: 500 | M32: 500 | N32: 600 | O32: 600 | P32: 600 | Q32: 600 | R32: 600 | S32: 600 | T32: 600 | U32: 600 | V32: 600 | W32: 700 | X32: 700 | Y32: 700 | Z32: 700 | AA32: 700 | AB32: 700 | AC32: 700 | AD32: 700 | AE32: 800（带液） | AF32: 800 | AG32: 800 | AH32: 800 | AI32: 800 | AJ32: 800 | AK32: 900 | AL32: 900 | AM32: 900 | AN32: 1000 | AO32: 1000 | AP32: 1000 | AQ32: 1100 | AR32: 1100
B33: 压缩机转速/rpm | C33: 5000 | D33: 5000 | E33: 5000 | F33: 5000 | G33: 5000 | H33: 5000 | I33: 5000 | J33: 5000 | K33: 5000 | L33: 5000 | M33: 5000 | N33: 5000 | O33: 5000 | P33: 5000 | Q33: 5000 | R33: 5000 | S33: 5000 | T33: 5000 | U33: 5000 | V33: 5000 | W33: 5000 | X33: 5000 | Y33: 5000 | Z33: 5000 | AA33: 5000 | AB33: 5000 | AC33: 5000 | AD33: 5000 | AE33: 5000 | AF33: 5000 | AG33: 5000 | AH33: 5000 | AI33: 5000 | AJ33: 5000 | AK33: 5000 | AL33: 5000 | AM33: 5000 | AN33: 5000 | AO33: 5000 | AP33: 5000 | AQ33: 5000 | AR33: 5000
B34: 膨胀阀开度 | C34: 380 | D34: 285 | E34: 300 | F34: 270 | G34: 275 | H34: 275 | I34: 270 | J34: 280 | K34: 330 | L34: 400 | M34: 530 | N34: 275 | O34: 300 | P34: 270 | Q34: 272 | R34: 275 | S34: 310 | T34: 380 | U34: 430 | V34: 500 | W34: 330 | X34: 275 | Y34: 270 | Z34: 268 | AB34: 375 | AF34: 300 | AG34: 275 | AH34: 271 | AI34: 268 | AJ34: 271 | AK34: 271 | AL34: 268 | AM34: 278 | AN34: 278 | AO34: 273 | AP34: 269 | AQ34: 276 | AR34: 270
B35: 制冷剂流量/kg·h-1 | C35: 95.4 | D35: 85.2 | E35: 115.3 | F35: 102.1 | G35: 106.5 | H35: 106.6 | I35: 100.8 | J35: 110.9 | K35: 118.3 | L35: 123.8 | M35: 132.4 | N35: 115.1 | O35: 119.7 | P35: 113.1 | Q35: 113.4 | R35: 132.3 | S35: 136.3 | T35: 139.1 | U35: 141.2 | V35: 143.6 | W35: 119.1 | X35: 113.9 | Y35: 112 | Z35: 110.4 | AB35: 136.5 | AC35: 137.8 | AD35: 139.6 | AE35: 143.7 | AF35: 121.3 | AG35: 116.1 | AH35: 113.6 | AI35: 112.2 | AJ35: 126.8 | AK35: 113.5 | AL35: 112 | AM35: 118.3 | AN35: 133.6 | AO35: 126.5 | AP35: 120.1 | AQ35: 148.2 | AR35: 137.2
B36: 室内侧风量/m3·h-1 | C36: 478.353 | D36: 478.749 | E36: 473.942 | F36: 476.312 | G36: 474.774 | H36: 475.045 | I36: 475.317 | J36: 476.487 | K36: 475.27 | L36: 473.866 | M36: 475.868 | N36: 475.093 | O36: 476.791 | P36: 477.748 | Q36: 477.873 | R36: 479.425 | S36: 478.144 | T36: 478.311 | U36: 478.439 | V36: 480.14 | W36: 478.587 | X36: 478.143 | Y36: 479.281 | Z36: 477.673 | AB36: 479.726 | AC36: 479.748 | AD36: 478.435 | AE36: 479.931 | AF36: 480.987 | AG36: 479.193 | AH36: 480.471 | AI36: 480.392 | AJ36: 478.553 | AK36: 478.369 | AL36: 478.313 | AM36: 479.02 | AN36: 480.712 | AO36: 480.535 | AP36: 478.931 | AQ36: 480.529 | AR36: 478.973
B37: 室外侧风量/m3·h-1 | C37: 4506.42 | D37: 4517.79 | E37: 4510.54 | F37: 4504.99 | G37: 4518.02 | H37: 4513.79 | I37: 4502.38 | J37: 4507.23 | K37: 4509.76 | L37: 4513.95 | M37: 4505.57 | N37: 4518.39 | O37: 4515.91 | P37: 4519.05 | Q37: 4514.73 | R37: 4501.74 | S37: 4518.35 | T37: 4513.07 | U37: 4512.16 | V37: 4504.14 | W37: 4516.84 | X37: 4512.19 | Y37: 4523.67 | Z37: 4495.72 | AB37: 4491.81 | AC37: 4495.2 | AD37: 4485.84 | AE37: 4491.94 | AF37: 4486.24 | AG37: 4490.24 | AH37: 4490.08 | AI37: 4495.77 | AJ37: 4480.09 | AK37: 4482.14 | AL37: 4481.88 | AM37: 4472.29 | AN37: 4493.16 | AO37: 4488.32 | AP37: 4494.89 | AQ37: 4487.79 | AR37: 4492.45
B38: 室内侧换热量//蒸发器/W | C38: 3978 | D38: 3704.28 | E38: 4603.03 | F38: 4817 | G38: 4818.25 | H38: 4618.73 | I38: 4580.64 | J38: 4675.77 | K38: 4625.49 | L38: 4567.78 | M38: 4434.35 | N38: 4842.65 | O38: 4670.62 | P38: 4945.81 | Q38: 4932.02 | R38: 4812.04 | S38: 4774.46 | T38: 4688.6 | U38: 4646.49 | V38: 4553.25 | W38: 4584.8 | X38: 4800.47 | Y38: 4913.42 | Z38: 4939.53 | AA38: 5000.57 | AB38: 4665.05 | AC38: 4624.49 | AD38: 4553.16 | AE38: 4510.7 | AF38: 4655.42 | AG38: 4843.19 | AH38: 4953.37 | AI38: 5005.28 | AJ38: 4748.78 | AK38: 4861 | AL38: 4880 | AM38: 4693.39 | AN38: 4571.23 | AO38: 4660.48 | AP38: 4746.94 | AQ38: 4764.27 | AR38: 4782.08
B39: 室内侧换热量/制冷剂/W | C39: {=C35/3600*([1]!Enthalpy("carbon dioxide","TP","SI",C17+273.15,C28)-[1]!Enthalpy("carbon dioxide","TP","SI",C14+273.15,C26))*1000} -> 4369.0953 | D39: {=D35/3600*([1]!Enthalpy("carbon dioxide","TP","SI",D17+273.15,D28)-[1]!Enthalpy("carbon dioxide","TP","SI",D14+273.15,D26))*1000} -> 4041.0202 | E39: {=E35/3600*([1]!Enthalpy("carbon dioxide","TP","SI",E17+273.15,E28)-[1]!Enthalpy("carbon dioxide","TP","SI",E14+273.15,E26))*1000} -> 5261.1333 | F39: {=F35/3600*([1]!Enthalpy("carbon dioxide","TP","SI",F17+273.15,F28)-[1]!Enthalpy("carbon dioxide","TP","SI",F14+273.15,F26))*1000} -> 5298.2631 | G39: {=G35/3600*([1]!Enthalpy("carbon dioxide","TP","SI",G17+273.15,G28)-[1]!Enthalpy("carbon dioxide","TP","SI",G14+273.15,G26))*1000} -> 5232.9278 | H39: {=H35/3600*([1]!Enthalpy("carbon dioxide","TP","SI",H17+273.15,H28)-[1]!Enthalpy("carbon dioxide","TP","SI",H14+273.15,H26))*1000} -> 5111.5263 | I39: {=I35/3600*([1]!Enthalpy("carbon dioxide","TP","SI",I17+273.15,I28)-[1]!Enthalpy("carbon dioxide","TP","SI",I14+273.15,I26))*1000} -> 5020.456 | J39: {=J35/3600*([1]!Enthalpy("carbon dioxide","TP","SI",J17+273.15,J28)-[1]!Enthalpy("carbon dioxide","TP","SI",J14+273.15,J26))*1000} -> 5175.3567 | ... AR39: {=AR35/3600*([1]!Enthalpy("carbon dioxide","TP","SI",AR17+273.15,AR28)-[1]!Enthalpy("carbon dioxide","TP","SI",AR14+273.15,AR26))*1000} -> 7996.4452
B40: 室外侧换热量//冷凝器/W
...

Sheet 压降分析
B1: 流量 | C1: =Sheet2!C35 -> 95.4
A2: 压降 | B2: 蒸发器 | C2: =Sheet2!C28-Sheet2!#REF! -> #REF!
B3: 蒸发器至储液器 | C3: =Sheet2!#REF!-Sheet2!C29 -> #REF!
B4: 储液器至吸气 | C4: =Sheet2!C29-Sheet2!C22 -> -2.8
B5: 排气至气冷 | C5: =Sheet2!C23-Sheet2!C24 -> 0.127
B6: 气冷 | C6: =Sheet2!C24-Sheet2!C25 -> -0.119
A28: 蒸发器压降 | B28: 原系统 | D28: 新系统 | F28: 三花
B29: 流量 | C29: 压降 | D29: 流量 | E29: 压降 | F29: 流量 | G29: 压降
D30: 100.3 | E30: 0.292
B31: 99 | C31: 0.539 | D31: 104.7 | E31: 0.322
B32: 105.2 | C32: 0.595 | D32: 106.3 | E32: 0.336 | F32: 106.19 | G32: 0.264
B33: 128.1 | C33: 0.825 | D33: 131.2 | E33: 0.509 | F33: 118.92 | G33: 0.324

Sheet Sheet3
B1: 原系统 | F1: 新系统 | J1: 三花
B2: 风量 | C2: 流量 | D2: 制冷量 | E2: COP | F2: 风量 | G2: 流量 | H2: 制冷量 | I2: COP | J2: 风量 | K2: 流量 | L2: 制冷量
B3: 302.079 | C3: 113 | D3: 2632.99 | E3: 0.61547218 | F3: 297.304 | G3: 100.3 | H3: 3564.06 | I3: 1.2753838 | J3: 200 | K3: 57.11 | L3: 2405
B4: 420.173 | C4: 129.3 | D4: 4043.3 | E4: 1.0752046 | F4: 421.097 | G4: 104.7 | H4: 4124.63 | I4: 1.4065234 | J4: 340 | K4: 89.37 | L4: 3870
B5: 420.571 | C5: 113.6 | D5: 3815.023 | E5: 1.3009456 | F5: 503.903 | G5: 106.3 | H5: 4380.4 | I5: 1.4763734 | J5: 420 | K5: 106.19 | L5: 4585
F6: 505.52 | G6: 131.2 | H6: 5018.8 | I6: 1.3105627 | J6: 500 | K6: 118.92 | L6: 5159
