Workbook

Sheet Sheet2
B1: 列0 | C1: 列1 | D1: 列2 | E1: 列3 | F1: 列4 | G1: 列5 | H1: 列6 | I1: 列7 | J1: 列8 | K1: 列9 | L1: 列10 | M1: 列11 | N1: 列12 | O1: 列13 | P1: 列14 | Q1: 列15 | R1: 列16
B2: 日期 | C2: 无回热 | D2: 全回热 | E2: 全回热 | F2: 全回热 | G2: 全回热 | H2: 全回热 | I2: 全回热 | J2: 全回热 | K2: 全回热 | L2: 全回热
A3: 类别 | B3: 项目 | C3: 组1 | D3: 组2 | E3: 组3 | F3: 组4 | G3: 组5 | H3: 组6 | I3: 组7 | J3: 组8 | K3: 组9 | L3: 组10 | M3: 组11 | N3: 组12 | O3: 组13 | P3: 组14 | Q3: 组15 | R3: 组16
A4: 环境参数 | B4: 室内干球 | C4: 27 | D4: 27.1 | E4: 27 | F4: 27 | G4: 26.9 | H4: 27 | I4: 27 | J4: 27 | K4: 27
B5: 室内湿球 | C5: 19.5 | D5: 19.5 | E5: 19.5 | F5: 19.5 | G5: 19.5 | H5: 19.5 | I5: 19.5 | J5: 19.6 | K5: 19.5
B6: 室外干球 | C6: 30.3 | D6: 29.8 | E6: 29.8 | F6: 29.8 | G6: 30 | H6: 30.2 | I6: 30.2 | J6: 29.9 | K6: 29.8
B7: 室外湿球 | C7: 22.4 | D7: 21.7 | E7: 21.7 | F7: 21.5 | G7: 22.6 | H7: 22.2 | I7: 22.2 | J7: 21.8 | K7: 21.8
A8: 温度/℃ | B8: 吸气温度 | C8: -2.5 | D8: 25.92 | E8: 25.16 | F8: 26.6 | G8: 15.63 | H8: 17.96 | I8: 18.84 | J8: -0.65 | K8: 0.65
B9: 排气温度 | C9: 111.99 | D9: 122.45 | E9: 124.45 | F9: 118.05 | G9: 101.38 | H9: 108.4 | I9: 114.62 | J9: 86.36 | K9: 95.09
B10: 室外换热进口 | C10: 109.13 | D10: 119.73 | E10: 119.74 | F10: 113.64 | G10: 98.43 | H10: 105.12 | I10: 110.61 | J10: 84.26 | K10: 92.58
B11: 室外换热出口 | C11: 30.15 | D11: 34.98 | E11: 29.48 | F11: 33.92 | G11: 36.7 | H11: 35.94 | I11: 35.65 | J11: 36.59 | K11: 34.36
B12: 回热器高压进口 | C12: 32.88 | D12: 34.85 | E12: 34.3 | F12: 35.14 | G12: 35.58 | H12: 35.31 | I12: 34.79 | J12: 34.79 | K12: 33.84
B13: 回热器高压出口 | C13: 32.6 | D13: 22.56 | E13: 221.07 | F13: 24.59 | G13: 19.92 | H13: 18.5 | I13: 16.89 | J13: 12.32 | K13: 10.66
B14: 阀前温度 | C14: 32.08 | D14: 22.2 | E14: 20.97 | F14: 24.53 | G14: 19.78 | H14: 18.42 | I14: 16.72 | J14: 12.53 | K14: 10.94
B15: 阀后温度 | C15: 5.12 | D15: 3.35 | E15: 2.89 | F15: 4.25 | G15: 5.05 | H15: 3.98 | I15: 3.15 | J15: 4.37 | K15: 3.24
B16: 主换热器进口 | C16: 4.89 | D16: 3.22 | E16: 2.79 | F16: 4.14 | G16: 5.02 | H16: 4.01 | I16: 3.23 | J16: 4.51 | K16: 3.37
B17: 主换热器出口 | C17: 1.33 | D17: 0.83 | E17: 0.48 | F17: 1.63 | G17: 2.81 | H17: 1.85 | I17: 1.2 | J17: 2.54 | K17: 1.62
B18: 储液器进口 | C18: 0.49 | D18: 0.27 | E18: -0.1 | F18: 0.98 | G18: 2.02 | H18: 1.09 | I18: 0.45 | J18: 1.65 | K18: 0.76
B19: 储液器出口 | C19: 0 | D19: -0.2 | E19: -0.54 | F19: 0.61 | G19: 1.59 | H19: 0.74 | I19: 0.12 | J19: 1.24 | K19: 0.42
B20: 回热器低压进口 | C20: 25.76 | D20: -1.88 | E20: -2.2 | F20: -1.09 | G20: -0.34 | H20: -1.14 | I20: -1.67 | J20: -0.86 | K20: -1.59
B21: 回热器低压出口 | C21: 30.55 | D21: 27.7 | E21: 27.08 | F21: 28.22 | G21: 18.74 | H21: 20.47 | I21: 21.31 | J21: 2.57 | K21: 4.33
A22: 压力/Mpa | B22: 吸气压力 | C22: 3.25 | D22: 3.21 | E22: 3.18 | F22: 3.27 | G22: 3.37 | H22: 3.29 | I22: 3.25 | J22: 3.31 | K22: 3.26
B23: 排气压力 | C23: 11.48 | D23: 8.83 | E23: 8.95 | F23: 8.6 | G23: 8.68 | H23: 8.82 | I23: 9.02 | J23: 9.21 | K23: 9.58
B24: 气冷进口 | C24: 11.495 | D24: 8.83 | E24: 8.946 | F24: 8.586 | G24: 8.666 | H24: 8.791 | I24: 8.968 | J24: 9.222 | K24: 9.568
B25: 气冷出口 | C25: 11.399 | D25: 8.678 | E25: 8.824 | F25: 8.445 | G25: 8.426 | H25: 8.631 | I25: 8.871 | J25: 9.031 | K25: 9.407
B26: 阀前压力 | C26: 11.276 | D26: 8.58 | E26: 8.71 | F26: 8.27 | G26: 8.329 | H26: 8.515 | I26: 8.864 | J26: 8.847 | K26: 9.29
B27: 主换热器进口 | C27: 3.934 | D27: 3.803 | E27: 3.765 | F27: 3.877 | G27: 3.98 | H27: 3.879 | I27: 3.793 | J27: 3.953 | K27: 3.847
B28: 主换热器出口 | C28: 3.559 | D28: 3.527 | E28: 3.494 | F28: 3.603 | G28: 3.711 | H28: 3.613 | I28: 3.567 | J28: 3.687 | K28: 3.605
B29: 储液器进口
A30: 性能 | B30: 电压/V | C30: 345 | D30: 345 | E30: 345 | F30: 345 | G30: 345 | H30: 345 | I30: 345 | J30: 345 | K30: 345
B31: 电流/A | C31: 9.6 | D31: 7.3 | E31: 7.4 | F31: 7.1 | G31: 7.2 | H31: 7.3 | I31: 7.5 | J31: 7.7 | K31: 8
B32: 充注量/g | C32: 800 | D32: 900 | E32: 900 | F32: 900 | G32: 1000 | H32: 1000 | I32: 1000 | J32: 1100 | K32: 1100
B33: 压缩机转速/rpm | C33: 5000 | D33: 5000 | E33: 5000 | F33: 5000 | G33: 5000 | H33: 5000 | I33: 5000 | J33: 5000 | K33: 5000
B34: 膨胀阀开度 | C34: 271 | D34: 271 | E34: 268 | F34: 278 | G34: 278 | H34: 273 | I34: 269 | J34: 276 | K34: 270
B35: 制冷剂流量/kg·h-1 | C35: 126.8 | D35: 113.5 | E35: 112 | F35: 118.3 | G35: 133.6 | H35: 126.5 | I35: 120.1 | J35: 148.2 | K35: 137.2
B36: 室内侧风量/m3·h-1 | C36: 478.553 | D36: 478.369 | E36: 478.313 | F36: 479.02 | G36: 480.712 | H36: 480.535 | I36: 478.931 | J36: 480.529 | K36: 478.973
B37: 室外侧风量/m3·h-1 | C37: 4480.09 | D37: 4482.14 | E37: 4481.88 | F37: 4472.29 | G37: 4493.16 | H37: 4488.32 | I37: 4494.89 | J37: 4487.79 | K37: 4492.45
B38: 室内侧换热量//蒸发器/W | C38: 4748.78 | D38: 4861 | E38: 4880 | F38: 4693.39 | G38: 4571.23 | H38: 4660.48 | I38: 4746.94 | J38: 4764.27 | K38: 4782.08
B39: 室内侧换热量/制冷剂/W | C39: =C35/3600*([1]!Enthalpy("carbon dioxide","TP","SI",C17+273.15,C28)-[1]!Enthalpy("carbon dioxide","TP","SI",C14+273.15,C26))*1000 -> #NAME? | D39: =D35/3600*([1]!Enthalpy("carbon dioxide","TP","SI",D17+273.15,D28)-[1]!Enthalpy("carbon dioxide","TP","SI",D14+273.15,D26))*1000 -> #NAME? | E39: =E35/3600*([1]!Enthalpy("carbon dioxide","TP","SI",E17+273.15,E28)-[1]!Enthalpy("carbon dioxide","TP","SI",E14+273.15,E26))*1000 -> #NAME? | F39: =F35/3600*([1]!Enthalpy("carbon dioxide","TP","SI",F17+273.15,F28)-[1]!Enthalpy("carbon dioxide","TP","SI",F14+273.15,F26))*1000 -> #NAME? | G39: =G35/3600*([1]!Enthalpy("carbon dioxide","TP","SI",G17+273.15,G28)-[1]!Enthalpy("carbon dioxide","TP","SI",G14+273.15,G26))*1000 -> #NAME? | H39: =H35/3600*([1]!Enthalpy("carbon dioxide","TP","SI",H17+273.15,H28)-[1]!Enthalpy("carbon dioxide","TP","SI",H14+273.15,H26))*1000 -> #NAME? | I39: =I35/3600*([1]!Enthalpy("carbon dioxide","TP","SI",I17+273.15,I28)-[1]!Enthalpy("carbon dioxide","TP","SI",I14+273.15,I26))*1000 -> #NAME? | J39: =J35/3600*([1]!Enthalpy("carbon dioxide","TP","SI",J17+273.15,J28)-[1]!Enthalpy("carbon dioxide","TP","SI",J14+273.15,J26))*1000 -> #NAME? | K39: =K35/3600*([1]!Enthalpy("carbon dioxide","TP","SI",K17+273.15,K28)-[1]!Enthalpy("carbon dioxide","TP","SI",K14+273.15,K26))*1000 -> #NAME?
B40: 室外侧换热量//冷凝器/W
...

Sheet 压降分析
B1: 流量 | C1: =Sheet2!C35 -> 126.8
A2: 压降 | B2: 蒸发器 | C2: =Sheet2!C27-Sheet2!C28 -> 0.375
B3: 蒸发器至储液器 | C3: =Sheet2!C28-Sheet2!C29 -> 3.559
B4: 储液器至吸气 | C4: =Sheet2!C29-Sheet2!C22 -> -3.25
B5: 排气至气冷 | C5: =Sheet2!C23-Sheet2!C24 -> -0.015
B6: 气冷 | C6: =Sheet2!C24-Sheet2!C25 -> 0.096
A28: 蒸发器压降 | B28: 原系统 | D28: 新系统 | F28: 三花
B29: 流量 | C29: 压降 | D29: 流量 | E29: 压降 | F29: 流量 | G29: 压降
D30: 100.3 | E30: 0.292
B31: 99 | C31: 0.539 | D31: 104.7 | E31: 0.322
B32: 105.2 | C32: 0.595 | D32: 106.3 | E32: 0.336 | F32: 106.19 | G32: 0.264
B33: 128.1 | C33: 0.825 | D33: 131.2 | E33: 0.509 | F33: 118.92 | G33: 0.324

Sheet Sheet3
B1: 原系统 | F1: 新系统 | J1: 三花
B2: 风量 | C2: 流量 | D2: 制冷量 | E2: COP | F2: 风量 | G2: 流量 | H2: 制冷量 | I2: COP | J2: 风量 | K2: 流量 | L2: 制冷量
B3: 302.079 | C3: 113 | D3: 2632.99 | E3: 0.61547218 | F3: 297.304 | G3: 100.3 | H3: 3564.06 | I3: 1.2753838 | J3: 200 | K3: 57.11 | L3: 2405
B4: 420.173 | C4: 129.3 | D4: 4043.3 | E4: 1.0752046 | F4: 421.097 | G4: 104.7 | H4: 4124.63 | I4: 1.4065234 | J4: 340 | K4: 89.37 | L4: 3870
B5: 420.571 | C5: 113.6 | D5: 3815.023 | E5: 1.3009456 | F5: 503.903 | G5: 106.3 | H5: 4380.4 | I5: 1.4763734 | J5: 420 | K5: 106.19 | L5: 4585
F6: 505.52 | G6: 131.2 | H6: 5018.8 | I6: 1.3105627 | J6: 500 | K6: 118.92 | L6: 5159
