Workbook

Sheet Sheet2
B1: 列0 | C1: 列1 | D1: 列2 | E1: 列3 | F1: 列4 | G1: 列5 | H1: 列6 | I1: 列7 | J1: 列8 | K1: 列9 | L1: 列10 | M1: 列11 | N1: 列12 | O1: 列13 | P1: 列14 | Q1: 列15 | R1: 列16
B2: 日期
A3: 类别 | B3: 项目 | C3: 组1 | D3: 组2 | E3: 组3 | F3: 组4 | G3: 组5 | H3: 组6 | I3: 组7 | J3: 组8 | K3: 组9 | L3: 组10 | M3: 组11 | N3: 组12 | O3: 组13 | P3: 组14 | Q3: 组15 | R3: 组16
A4: 环境参数 | B4: 室内干球 | C4: 27 | D4: 27 | E4: 27 | F4: 40 | G4: 40 | H4: 40 | I4: 40
B5: 室内湿球 | C5: 19.5 | D5: 19.5 | E5: 19.5 | F5: 27.7 | G5: 27.7 | H5: 27.7 | I5: 27.7
B6: 室外干球 | C6: 30 | D6: 30 | E6: 30 | F6: 40 | G6: 40 | H6: 40 | I6: 40
B7: 室外湿球 | C7: 20.6 | D7: 20.6 | E7: 20.3 | F7: 27.7 | G7: 27.7 | H7: 27.7 | I7: 27.7
A8: 温度/℃ | B8: 吸气温度 | C8: 2.14 | D8: 2.13 | E8: 3.56 | F8: 32.82 | G8: 22.27 | H8: 23.88 | I8: 18.4
B9: 排气温度 | C9: 117.39 | D9: 113.08 | E9: 106.55 | F9: 136.14 | G9: 139.14 | H9: 133.18 | I9: 138.57
B10: 室外换热进口 | C10: 115.77 | D10: 110.38 | E10: 105.68 | F10: 134.89 | G10: 135.57 | H10: 130.94 | I10: 135.09
B11: 室外换热出口 | C11: 32.21 | F11: 44.34 | G11: 45.96 | H11: 46.64 | I11: 44.08
B12: 回热器高压进口 | C12: 32.45 | D12: 31.74 | E12: 31.44 | F12: 44.23 | G12: 45.74 | H12: 46.33 | I12: 43.83
B13: 回热器高压出口 | C13: 30.59 | D13: 30.38 | E13: 30.27 | F13: 30.61 | G13: 35.67 | H13: 36.72 | I13: 36.36
B14: 阀前温度 | C14: 30.12 | D14: 29.77 | E14: 29.54 | F14: 31.22 | G14: 35.46 | H14: 36.93 | I14: 23.82
B15: 阀后温度 | C15: 5.28 | D15: 4.48 | E15: 5.08 | F15: 13.55 | G15: 12.48 | H15: 13.31 | I15: 5.54
B16: 主换热器进口 | C16: 5.4 | D16: 4.72 | E16: 5.5 | F16: 13.81 | G16: 12.45 | H16: 13.25 | I16: 5.67
B17: 主换热器出口 | C17: 2.38 | D17: 2.22 | E17: 3.79 | F17: 11.5 | G17: 7.82 | H17: 8.39 | I17: 0.35
B18: 储液器进口 | C18: 1.32 | D18: 1.34 | E18: 3.07 | F18: 10.57 | G18: 6.27 | H18: 6.75 | I18: -1.51
B19: 储液器出口 | C19: 0.97 | D19: 1.08 | E19: 2.92 | F19: 10.39 | G19: 5.79 | H19: 6.3 | I19: -1.81
B20: 回热器低压进口 | C20: 7.22 | D20: 8.53 | E20: 10.95 | F20: 8.62 | G20: 4.29 | H20: 4.46 | I20: -2.39
B21: 回热器低压出口 | C21: 31.76 | D21: 4.48 | E21: 30.9 | F21: 34.61 | G21: 38.81 | H21: 39.24 | I21: 39.66
A22: 压力/Mpa | B22: 吸气压力 | C22: 3.39 | D22: 3.42 | E22: 3.56 | F22: 4.26 | G22: 3.78 | H22: 3.8 | I22: 3.11
B23: 排气压力 | C23: 11.81 | D23: 11.82 | E23: 11.84 | F23: 11.9 | G23: 11.99 | H23: 11.48 | I23: 10.46
B24: 阀前压力 | C24: 11.582 | D24: 11.656 | E24: 11.525 | F24: 11.773 | G24: 11.673 | H24: 10.947 | I24: 10.074
B25: 主换热器进口 | C25: 3.893 | D25: 3.883 | E25: 3.912 | F25: 4.848 | G25: 4.697 | H25: 4.759 | I25: 3.963
B26: 主换热器出口 | C26: 3.549 | D26: 3.607 | E26: 3.636 | F26: 4.553 | G26: 4.139 | H26: 4.22 | I26: 3.424
A27: 性能 | B27: 电压 | C27: 345 | D27: 345 | E27: 345 | F27: 345 | G27: 345 | H27: 345 | I27: 345
B28: 电流/A | C28: 9.3 | D28: 7.8 | E28: 5.8 | F28: 10 | G28: 14.4 | H28: 13.8 | I28: 12.5
B29: 充注量/g
B30: 压缩机转速/rpm | C30: 4700 | D30: 4000 | E30: 3000 | F30: 5000 | G30: 7000 | H30: 7000 | I30: 7000
B31: 膨胀阀开度 | C31: 267 | D31: 262 | E31: 247 | F31: 275 | G31: 360 | H31: 460
B32: 制冷剂流量/kg·h-1 | C32: 118.7 | D32: 10.7 | E32: 89.6 | F32: 141.5 | G32: 180.5 | H32: 188.5 | I32: 151.4
B33: 室内侧风量/m3·h-1 | C33: 496.9 | D33: 419.661 | E33: 341.23 | F33: 482.056 | G33: 480.15 | H33: 481.95 | I33: 480.242
B34: 室外侧风量/m3·h-1 | C34: 4454 | D34: 5365.64 | E34: 5365.83 | F34: 3681.69 | G34: 3691.86 | H34: 3668.74 | I34: 5473.87
B35: 室内侧换热量//蒸发器/W | C35: 4668 | D35: 4268.94 | E35: 3586 | F35: 5548.06 | G35: 6332.99 | H35: 6220.53 | I35: 4770.22
B36: 压缩机功率/W | C36: =C27*C28 -> 3208.5 | D36: =D27*D28 -> 2691 | E36: =E27*E28 -> 2001 | F36: =F27*F28 -> 3450 | G36: =G27*G28 -> 4968 | H36: =H27*H28 -> 4761 | I36: =I27*I28 -> 4312.5
B37: 室内侧COP | C37: =C35/C36 -> 1.4548855 | D37: =D35/D36 -> 1.5863768 | E37: =E35/E36 -> 1.7921039 | F37: =F35/F36 -> 1.6081333 | G37: =G35/G36 -> 1.2747564 | H37: =H35/H36 -> 1.3065595 | I37: =I35/I36 -> 1.106138
B38: 室内侧COP/制冷剂 | C38: =#REF!/C36 -> #REF! | D38: =#REF!/D36 -> #REF! | E38: =#REF!/E36 -> #REF! | F38: =#REF!/F36 -> #REF!
B39: 室内出风干球/℃ | C39: 9.05 | D39: 8.22 | F39: 19.02 | G39: 17.26 | H39: 17.55 | I39: 8.58
B40: 室内出风湿球/℃ | C40: 8.9 | D40: 8.12 | F40: 18.39 | G40: 16.71 | H40: 16.99 | I40: 8.33
...

Sheet 压降分析
B1: 流量 | C1: 100.3 | D1: 104.7 | E1: 106.3 | F1: 131.2
A2: 压降 | B2: 蒸发器 | C2: =Sheet2!C25-Sheet2!C26 -> 0.344 | D2: =Sheet2!D25-Sheet2!D26 -> 0.276 | E2: =Sheet2!E25-Sheet2!E26 -> 0.276 | F2: =Sheet2!F24-Sheet2!F26 -> 7.22
B3: 蒸发器至储液器 | C3: =Sheet2!C26-Sheet2!#REF! -> #REF! | D3: =Sheet2!D25-Sheet2!D26 -> 0.276 | E3: =Sheet2!E25-Sheet2!E26 -> 0.276 | F3: =Sheet2!F24-Sheet2!F26 -> 7.22
B4: 储液器至吸气 | C4: =Sheet2!#REF!-Sheet2!C22 -> #REF! | D4: =Sheet2!#REF!-Sheet2!D22 -> #REF! | E4: =Sheet2!#REF!-Sheet2!E22 -> #REF! | F4: =Sheet2!#REF!-Sheet2!F22 -> #REF!
B5: 排气至气冷 | D5: =Sheet2!D23-Sheet2!#REF! -> #REF! | E5: =Sheet2!E23-Sheet2!#REF! -> #REF! | F5: =Sheet2!F23-Sheet2!#REF! -> #REF!
B6: 气冷
B27: 原系统 | D27: 新系统 | F27: 三花
A28: 蒸发器压降 | B28: 流量 | C28: 压降 | D28: 流量 | E28: 压降 | F28: 流量
D29: 100.3 | E29: 0.292 | G29: 压降
B30: 99 | C30: 0.539 | D30: 104.7 | E30: 0.322
B31: 105.2 | C31: 0.595 | D31: 106.3 | E31: 0.336 | F31: 106.19
B32: 128.1 | C32: 0.825 | D32: 131.2 | E32: 0.509 | F32: 118.92 | G32: 0.264
G33: 0.324

Sheet Sheet3
B1: 原系统 | F1: 新系统 | J1: 三花
B2: 风量 | C2: 流量 | D2: 制冷量 | E2: COP | F2: 风量 | G2: 流量 | H2: 制冷量 | I2: COP | J2: 风量 | K2: 流量 | L2: 制冷量
B3: 302.079 | C3: 113 | D3: 2632.99 | E3: 0.61547218 | F3: 297.304 | G3: 100.3 | H3: 3564.06 | I3: 1.2753838 | J3: 200 | K3: 57.11 | L3: 2405
B4: 420.173 | C4: 129.3 | D4: 4043.3 | E4: 1.0752046 | F4: 421.097 | G4: 104.7 | H4: 4124.63 | I4: 1.4065234 | J4: 340 | K4: 89.37 | L4: 3870
B5: 420.571 | C5: 113.6 | D5: 3815.023 | E5: 1.3009456 | F5: 503.903 | G5: 106.3 | H5: 4380.4 | I5: 1.4763734 | J5: 420 | K5: 106.19 | L5: 4585
F6: 505.52 | G6: 131.2 | H6: 5018.8 | I6: 1.3105627 | J6: 500 | K6: 118.92 | L6: 5159
